Workbook

Sheet output_file_it3
A1: Doi | B1: DB | C1: Title | D1: Abstract | E1: keywords | F1: Terms category 1 | G1: Terms category 2 | H1: Terms 1 | I1: Terms 2 | J1: Length T1 | K1: Length T2
A2: /doi/10.1145/3590003.3590014 | B2: ACM | C2: Garment Metaverse: Parametric Digital Human and Dynamic Scene Try-on | D2: As a new concept, the metaverse has been widely concerned by the industry, academia, media and the public. Many domestic and foreign companies have also set up in the field of the metaverse. The traditional 2D and 3D virtual fitting has not achieved breakthrough and development because of the technical problems of authenticity and timeliness. With this in mind, we developed a virtual fitting system based on the metaverse community, which includes two modules: parameterized virtual digital human modeling and multi-scene and multi-action fitting. The system realizes the construction of individualized virtual digital person. As the medium between the metaverse clothing community and the real world, it is used to achieve multi-category dynamic fitting display actions in the meta-universe clothing community platform for multi-category scenes. The system integrates the high simulation and synchronization of the metaverse with the virtual fitting system, to break the barriers of traditional virtual fitting technology and realize the combination of the garment industry and the metaverse. The experimental results show that the system can realize the construction of virtual digital human in 2.1ms at the fastest and realize the dynamic display of multi-action and multi-scene fitting. | E2: 3D face reconstruction, Digital human, Metaverse, Virtual try-on | F2: 900 - No match | G2: 900 - No match | H2: [] | I2: [] | J2: =+LEN(H2) -> 2 | K2: =+LEN(I2) -> 2
A3: /doi/10.1109/MODELS.2017.28 | B3: ACM | C3: DREAMS toolchain: model-driven engineering of mixed-criticality systems | D3: Mixed-criticality systems (MCS) aim at boosting the integration density in safety-critical systems, resulting into efficient systems, while simultaneously providing increased performance. The DREAMS project provides a cross-domain architectural style for MCS based on networked, virtualized multi-cores controlled by hierarchical resource managers. However, the availability of a platform is only one side of the coin: deploying mixed-critical applications to shared resources typically requires design-time configurations (e.g., to ensure real-time constraints or separation constraints mandated by safety regulations). These configurations are the outcome of complex optimization problems which are intractable in a manual process that also hardly can guarantee the consistency of all deployable artefacts nor their traceability to the requirements. However, existing toolchains lack support for MCS integration, and particularly DREAMS' advanced platform capabilities. | E3: design space exploration, mixed-criticalitity systems, model-driven engineering, product-lines, resource management, safety | F3: 900 - No match | G3: 900 - No match | H3: [] | I3: [] | J3: =+LEN(H3) -> 2 | K3: =+LEN(I3) -> 2
A4: /doi/10.1145/3626772.3657818 | B4: ACM | C4: AutoDCS: Automated Decision Chain Selection in Deep Recommender Systems | D4: Multi-behavior recommender systems (MBRS) have been commonly deployed on real-world industrial platforms for their superior advantages in understanding user preferences and mitigating data sparsity. However, the cascade graph modeling paradigm adopted in mainstream MBRS usually assumes that users will refer to all types of behavioral knowledge they have when making decisions about target behaviors, i.e., use all types of behavioral interactions indiscriminately when modeling and predicting target behaviors for each user. We call this a full decision chain constraint and argue that it may be too strict by ignoring that different types of behavioral knowledge have varying importance for different users. In this paper, we propose a novel automated decision chain selection (AutoDCS) framework to relax this constraint, which can consider each user's unique decision dependencies and select a reasonable set of behavioral knowledge to activate for the prediction of target behavior. Specifically, AutoDCS first integrates some existing MBRS methods in a base cascade module to obtain a set of behavior-aware embeddings. Then, a bilateral matching gating mechanism is used to select an exclusive set of behaviors for the current user-item pair to form a decision chain, and the corresponding behavior-augmented embeddings are selectively activated. Subsequently, AutoDCS combines the behavior-augmented and original behavior-aware embeddings to predict the target behavior. Finally, we evaluate AutoDCS and demonstrate its effectiveness through experiments over four public multi-behavior benchmarks. | E4: bilateral matching gate, decision chain selection, deep recommender system, multi-behavior learning | F4: 3 - Modified acrs | G4: 900 - No match | H4: ['MBRS'] | I4: [] | J4: =+LEN(H4) -> 8 | K4: =+LEN(I4) -> 2
A5: /doi/10.1145/3458864.3466868 | B5: ACM | C5: A real-time experimentation platform for sub-6 GHz and millimeter-wave MIMO systems | D5: The performance of wireless communication systems is evolving rapidly, making it difficult to build experimentation platforms that meet the hardware requirements of new standards. The bandwidth of current systems ranges from 160 MHz for IEEE 802.11ac/ax to 2 GHz for Millimeter-Wave (mm-wave) IEEE 802.11ad/ay, and they support up to 8 spatial MIMO streams. Mobile 5G and beyond systems have a similarly diverse set of requirements. | E5: FPGA, MIMO, millimeter wave, multi-band, phased antenna array, testbed | F5: 900 - No match | G5: 900 - No match | H5: [] | I5: [] | J5: =+LEN(H5) -> 2 | K5: =+LEN(I5) -> 2
A6: /doi/10.1145/3660043.3660053 | B6: ACM | C6: The Research on â€œVirtual-real Integration, Multi-level Progressiveâ€ Practical Teaching: Take the Course â€œComprehensive Design and Production of the Internet of Things (Perception Layer)â€ as An Example | D6: The course "Comprehensive Design and Production of the Internet of Things (Perception Layer)" takes the information acquisition system of the perception Layer of the Internet of Things as the design direction, and completes the design and production of the system, including the construction of hardware circuits and the design of control programs. It is a typical offline practical training course. In order to solve the key points of practical courses, such as low classroom utilization, students â€œfishing in troubled watersâ€, and offline suspension of classes in epidemic areas, this case has been designed in teaching content, teaching design, and experimental methods to develop a â€œvirtual-real integration, multi-level progressiveâ€ teaching model. In terms of teaching content and teaching design, through the route of â€œbasic knowledge â†’ module practice â†’ project actual combatâ€, and with a more detailed and reasonable evaluation system, students can be guided from shallow to deep, easy first and then difficult, from simple to complex to learn and gradually improve, so as to stimulate students' interest in learning and improve practical innovation ability; In terms of experimental teaching methods, the Tinkercad simulation platform is introduced to implement a â€œvirtual-real fusionâ€ teaching plan. Students can combine the simulation platform with physical production to meet the teaching requirements of â€œsuspension of classes and non-stop learningâ€ during the epidemic, get rid of the limitations of physical components, and ensure that students can complete the design of the circuit and the debugging of the program anyway, and the teaching goals of the course can be achieved. | F6: 900 - No match | G6: 900 - No match | H6: [] | I6: [] | J6: =+LEN(H6) -> 2 | K6: =+LEN(I6) -> 2
A7: /doi/10.1145/3569470 | B7: ACM | C7: TransFloor: Transparent Floor Localization for Crowdsourcing Instant Delivery | D7: Smart on-demand delivery services require accurate indoor localization to enhance the system-human synergy experience of couriers in complex multi-story malls and platform construction. Floor localization is an essential part of indoor positioning, which can provide floor/altitude data support for upper-level 3D indoor navigation services (e.g., delivery route planning) to improve delivery efficiency and optimize order dispatching strategies. We argue that due to label dependence and device dependence, the existing floor localization methods cannot be flexibly deployed on a large scale in numerous multi-story malls across the country, nor can they apply to all couriers/users on the platform. This paper proposes a novel self-evolving and user-transparent floor localization system named TransFloor, based on crowdsourcing delivery data (e.g., order status and sensors data) without additional label investment and specialized equipment constraints. TransFloor consists of an unsupervised barometer-based module--IOD-TKPD and an NLP-inspired Wi-Fi-based module--Wifi2Vec, and Self-Labeling is a perfect bridge between both to completely achieve label-free and device-independent floor positioning. In addition, TransFloor is designed as a lightweight plugin embedded into the platform without refactoring the existing architecture, and it has been deployed nationwide to adaptively launch real-time accurate 3D/floor positioning services for numerous crowdsourcing couriers. We evaluate TransFloor on real-world records from an instant delivery platform (involving 672,282 orders, 7,390 couriers, and 6,206 merchants in 388 malls during two months). It can achieve an average accuracy of 94.61% and demonstrate good robustness to device heterogeneity and adaptive durability, outperforming existing state-of-the-art methods. Crucially, it can effectively improve user satisfaction and reduce overdue delivery by providing accurate floor navigation information in complex multi-story malls. As a case study, the platform reduces erroneous order scheduling by 60% and overdue delivery by 2.7%, and increases delivery efficiency by reducing courier arrival time by 12.27 seconds accounting for 7.29%. We believe that the key ideas of TransFloor can be extended to other crowdsourcing scenarios for the public further. | E7: 3D indoor localization, Crowdsourcing, Floor localization, Instant delivery | F7: 900 - No match | G7: 900 - No match | H7: [] | I7: [] | J7: =+LEN(H7) -> 2 | K7: =+LEN(I7) -> 2
A8: /doi/10.1145/3637528.3671612 | B8: ACM | C8: ADSNet: Cross-Domain LTV Prediction with an Adaptive Siamese Network in Advertising | D8: Advertising platforms have evolved in estimating Lifetime Value (LTV) to better align with advertisers' true performance metric which considers cumulative sum of purchases a customer contributes over a period. Accurate LTV estimation is crucial for the precision of the advertising system and the effectiveness of advertisements. However, the sparsity of real-world LTV data presents a significant challenge to LTV predictive model(i.e., pLTV), severely limiting the their capabilities. Therefore, we propose to utilize external data, in addition to the internal data of advertising platform, to expand the size of purchase samples and enhance the LTV prediction model of the advertising platform. To tackle the issue of data distribution shift between internal and external platforms, we introduce an Adaptive Difference Siamese Network (ADSNet), which employs cross-domain transfer learning to prevent negative transfer. Specifically, ADSNet is designed to learn information that is beneficial to the target domain. We introduce a gain evaluation strategy to calculate information gain, aiding the model in learning helpful information for the target domain and providing the ability to reject noisy samples, thus avoiding negative transfer. Additionally, we also design a Domain Adaptation Module as a bridge to connect different domains, reduce the distribution distance between them, and enhance the consistency of representation space distribution. We conduct extensive offline experiments and online A/B tests on a real advertising platform. Our proposed ADSNet method outperforms other methods, improving GINI by 2%. The ablation study highlights the importance of the gain evaluation strategy in negative gain sample rejection and improving model performance. Additionally, ADSNet significantly improves long-tail prediction. The online A/B tests confirm ADSNet's efficacy, increasing online LTV by 3.47% and GMV by 3.89%. | E8: adaptive cross-domain transfer learning, computational advertising, lifetime value prediction | F8: 900 - No match | G8: 900 - No match | H8: [] | I8: [] | J8: =+LEN(H8) -> 2 | K8: =+LEN(I8) -> 2
A9: /doi/10.1145/3592609 | B9: ACM | C9: Multi-criteria Optimization of Real-time DAGs on Heterogeneous Platforms under P-EDF | D9: This article tackles the problem of optimal placement of complex real-time embedded applications on heterogeneous platforms. Applications are composed of directed acyclic graphs of tasks, with each directed-acyclic-graph (DAG) having a minimum inter-arrival period for its activation requests and an end-to-end deadline within which all of the computations need to terminate since each activation. The platforms of interest are heterogeneous power-aware multi-core platforms with Dynamic Voltage and Frequency Scaling (DVFS) capabilities, including big.LITTLE Arm architectures and platforms with GPU or FPGA hardware accelerators with Dynamic Partial Reconfiguration capabilities. Tasks can be deployed on CPUs using partitioned EDF-based scheduling. Additionally, some of the tasks may have an alternate implementation available for one of the accelerators on the target platform, which are assumed to serve requests in non-preemptive FIFO order. The system can be optimized by minimizing power consumption, respecting precise timing constraints, maximizing the applicationsâ€™ slack, respecting given power consumption constraints, or even a combination of these, in a multi-objective formulation. | E9: End-to-end timing requirements, energy efficiency, DVFS, software-to-hardware mapping, mixed-integer quadratic constraint programming, heuristic optimization, Linux kernel, SCHED_DEADLINE | F9: 900 - No match | G9: 900 - No match | H9: [] | I9: [] | J9: =+LEN(H9) -> 2 | K9: =+LEN(I9) -> 2
A10: /doi/10.1145/3583780.3614978 | B10: ACM | C10: Multi-modal Mixture of Experts Represetation Learning for Sequential Recommendation | D10: Within online platforms, it is critical to capture the dynamic user preference from the sequential interaction behaviors for making accurate recommendation over time. Recently, significant progress has been made in sequential recommendation with deep learning. However, existing neural sequential recommender often suffer from the data sparsity issue in real-world applications. | E10: multi-modal recommendation, user behavior modeling | F10: 900 - No match | G10: 900 - No match | H10: [] | I10: [] | J10: =+LEN(H10) -> 2 | K10: =+LEN(I10) -> 2
A11: /doi/10.1145/3589334.3645697 | B11: ACM | C11: Is It Safe to Share Your Files? An Empirical Security Analysis of Google Workspace | D11: The increasing demand for remote work and virtual interactions has heightened the usage of business collaboration platforms~(BCPs), with Google Workspace as a prominent example. These platforms enhance team collaboration by integrating Google Docs, Slides, Calendar, and feature-rich third-party applications (add-ons). However, such integration of multiple users and entities has inadvertently introduced new and complex attack surfaces, elevating security and privacy risks in resource management to unprecedented levels. In this study, we conduct a systematic study on the effectiveness of the cross-entity resource management in Google Workspace, the most popular BCP. Our study unveils the access control enforcement in real-world BCPs for the first time. Based on this, we formulate the attack surfaces inherent in BCPs and conduct a comprehensive assessment, pinpointing three vulnerability types leading to distinct attacks. An analysis of 4,732 marketplace add-ons reveals that approximately 70% are potentially vulnerable to these attacks. We propose robust countermeasures to improve BCP security, urging immediate action and setting a foundation for future research. | E11: Google workspace, add-ons, security vulnerabilities, sharing | F11: 900 - No match | G11: 2 - Complete terms | H11: [] | I11: ['collaboration'] | J11: =+LEN(H11) -> 2 | K11: =+LEN(I11) -> 17
A12: /doi/10.1145/3632953 | B12: ACM | C12: Fine-grain Quantitative Analysis of Demand Paging in Unified Virtual Memory | D12: The abstraction of a shared memory space over separate CPU and GPU memory domains has eased the burden of portability for many HPC codebases. However, users pay for ease of use provided by system-managed memory with a moderate-to-high performance overhead. NVIDIA Unified Virtual Memory (UVM) is currently the primary real-world implementation of such abstraction and offers a functionally equivalent testbed for in-depth performance study for both UVM and future Linux Heterogeneous Memory Management (HMM) compatible systems. The continued advocacy for UVM and HMM motivates improvement of the underlying system. We focus on UVM-based systems and investigate the root causes of UVM overhead, a non-trivial task due to complex interactions of multiple hardware and software constituents and the desired cost granularity. | E12: Unified Virtual Memory, Heterogeneous Memory Management, Virtual Memory, GPGPU, Accelerated Computing | F12: 900 - No match | G12: 900 - No match | H12: [] | I12: [] | J12: =+LEN(H12) -> 2 | K12: =+LEN(I12) -> 2
A13: /doi/10.1145/3495018.3495469 | B13: ACM | C13: Development of Digital Signal Processing Simulation Platform Based on DSP and FPGA Cooperative Processing Technology | D13: As digital signals are widely used in various fields such as technology, communications, and software, the digital signal processing platform is part of a long-base tracking system used to perform signal detection and placement. Compared with the traditional analog signal processing platform based on the digital signal processing simulation platform based on DSP and FPGA co-processing technology, the digital signal processing system not only has more advantages in terms of sensitivity and accuracy, but also has lower development cost and Wider application environment requirements. DSP multi-core board and DSP core, FPGA core signal receiving board and back-end circuit design have very important significance. The function of software design is to collect data from the FPGA board and transmit the data to the multi-core DSP through the PCIE bus. DSP and FPGA provide great help for the design of hardware installation. Pay special attention to the circuit design of multi-core DSP board with multi-core DSP, FPGA nuclear signal receiving board and backplane. The function that the software design realizes is FPGA board card gathers the data signal. This paper analyzes the relevant characteristics and theoretical knowledge of DSP and FPGA co-processing technology, transmits data to the multi-core DSP board through the PCIE bus, completes the relevant detection of multi-channel signals on the multi-core DSP board, and realizes the development of a digital signal processing simulation platform. The final result of the research shows that when the real running time is 1523ms, the virtual simulation time is 123ms. When the real running time increases, the virtual simulation time also increases, showing a proportional relationship. The virtual simulation time has a shorter and faster running time. | F13: 900 - No match | G13: 900 - No match | H13: [] | I13: [] | J13: =+LEN(H13) -> 2 | K13: =+LEN(I13) -> 2
A14: /doi/10.1145/3539618.3592018 | B14: ACM | C14: MDDL: A Framework for Reinforcement Learning-based Position Allocation in Multi-Channel Feed | D14: Nowadays, the mainstream approach in position allocation system is to utilize a reinforcement learning model to allocate appropriate locations for items in various channels and then mix them into the feed. There are two types of data employed to train reinforcement learning (RL) model for position allocation, named strategy data and random data. Strategy data is collected from the current online model, it suffers from an imbalanced distribution of stateaction pairs, resulting in severe overestimation problems during training. On the other hand, random data offers a more uniform distribution of state-action pairs, but is challenging to obtain in industrial scenarios as it could negatively impact platform revenue and user experience due to random exploration. As the two types of data have different distributions, designing an effective strategy to leverage both types of data to enhance the efficacy of the RL model training has become a highly challenging problem. In this study, we propose a framework namedMulti-Distribution Data Learning (MDDL) to address the challenge of effectively utilizing both strategy and random data for training RL models on mixed multi-distribution data. Specifically, MDDL incorporates a novel imitation learning signal to mitigate overestimation problems in strategy data and maximizes the RL signal for random data to facilitate effective learning. In our experiments, we evaluated the proposed MDDL framework in a real-world position allocation system and demonstrated its superior performance compared to the previous baseline. MDDL has been fully deployed on the Meituan food delivery platform and currently serves over 300 million users. | E14: multi-distribution data learning, position allocation, reinforcement learning | F14: 900 - No match | G14: 900 - No match | H14: [] | I14: [] | J14: =+LEN(H14) -> 2 | K14: =+LEN(I14) -> 2
A15: /doi/10.1109/ASE56229.2023.00135 | B15: ACM | C15: An Empirical Study of Malicious Code In PyPI Ecosystem | D15: PyPI provides a convenient and accessible package management platform to developers, enabling them to quickly implement specific functions and improve work efficiency. However, the rapid development of the PyPI ecosystem has led to a severe problem of malicious package propagation. Malicious developers disguise malicious packages as normal, posing a significant security risk to end-users. | E15: PyPi ecosystem, package management, malicious code, mirror source, lifecycle portrait | F15: 900 - No match | G15: 900 - No match | H15: [] | I15: [] | J15: =+LEN(H15) -> 2 | K15: =+LEN(I15) -> 2
A16: /doi/10.14778/3476311.3476372 | B16: ACM | C16: Towards a polyglot framework for factorized ML | D16: Optimizing machine learning (ML) workloads on structured data is a key concern for data platforms. One class of optimizations called "factorized ML" helps reduce ML runtimes over multi-table datasets by pushing ML computations down through joins, avoiding the need to materialize such joins. The recent Morpheus system | F16: 900 - No match | G16: 900 - No match | H16: [] | I16: [] | J16: =+LEN(H16) -> 2 | K16: =+LEN(I16) -> 2
A17: /doi/10.1145/3459637.3482214 | B17: ACM | C17: Variational Cross-Network Embedding for Anonymized User Identity Linkage | D17: User identity linkage (UIL) task aims to infer the identical users between different social networks/platforms. Existing models leverage the labeled inter-linkages or high-quality user attributes to make predictions. Nevertheless, it is often difficult or even impossible to obtain such information in real-world applications. To this end, we in this paper focus on studying an Anonymized User Identity Linkage (AUIL) problem wherein neither labeled anchor users nor attributes are available. To handle such a practical and challenging task, we propose a novel and concise unsupervised embedding method, VCNE, by utilizing the network structural information. Concretely, considering the inherent properties of structural diversity in the AUIL problem, we introduce a variational cross-network embedding learning framework to jointly study the Gaussian embeddings instead of the existing deterministic embedding from the angle of vector space. The multi-facet experiments on both real-world and synthetic datasets demonstrate that VCNE not only outperforms all baselines to a large extent but also be more robust to the different-level diversities and sparsities of the networks. | E17: gaussian embedding, user identity linkage, variational auto-encoders | F17: 900 - No match | G17: 900 - No match | H17: [] | I17: [] | J17: =+LEN(H17) -> 2 | K17: =+LEN(I17) -> 2
A18: /doi/10.1145/3552326.3567487 | B18: ACM | C18: Making Dynamic Page Coalescing Effective on Virtualized Clouds | D18: Using huge pages has become a mainstream method to reduce address translation overhead for big memory workloads in modern computer systems. To create huge pages, system software usually uses page coalescing methods to dynamically combine contiguous base pages. Though page coalescing methods help effectively reduce address translation overhead on native systems, as the paper shows, their effectiveness is substantially undermined on virtualized platforms. | E18: cloud computing, memory management, virtualization, operating systems | F18: 900 - No match | G18: 900 - No match | H18: [] | I18: [] | J18: =+LEN(H18) -> 2 | K18: =+LEN(I18) -> 2
A19: /doi/10.1145/3485983.3494850 | B19: ACM | C19: OnSlicing: online end-to-end network slicing with reinforcement learning | D19: Network slicing allows mobile network operators to virtualize infrastructures and provide customized slices for supporting various use cases with heterogeneous requirements. Online deep reinforcement learning (DRL) has shown promising potential in solving network problems and eliminating the simulation-to-reality discrepancy. Optimizing cross-domain resources with online DRL is, however, challenging, as the random exploration of DRL violates the service level agreement (SLA) of slices and resource constraints of infrastructures. In this paper, we propose OnSlicing, an online end-to-end network slicing system, to achieve minimal resource usage while satisfying slices' SLA. OnSlicing allows individualized learning for each slice and maintains its SLA by using a novel constraint-aware policy update method and proactive baseline switching mechanism. OnSlicing complies with resource constraints of infrastructures by using a unique design of action modification in slices and parameter coordination in infrastructures. OnSlicing further mitigates the poor performance of online learning during the early learning stage by offline imitating a rule-based solution. Besides, we design four new domain managers to enable dynamic resource configuration in radio access, transport, core, and edge networks, respectively, at a timescale of subseconds. We implement OnSlicing on an end-to-end slicing testbed designed based on OpenAirInterface with both 4G LTE and 5G NR, OpenDayLight SDN platform, and OpenAir-CN core network. The experimental results show that OnSlicing achieves 61.3% usage reduction as compared to the rule-based solution and maintains nearly zero violation (0.06%) throughout the online learning phase. As online learning is converged, OnSlicing reduces 12.5% usage without any violations as compared to the state-of-the-art online DRL solution. | E19: end-to-end network slicing, online deep reinforcement learning, resource orchestration | F19: 900 - No match | G19: 900 - No match | H19: [] | I19: [] | J19: =+LEN(H19) -> 2 | K19: =+LEN(I19) -> 2
A20: /doi/10.1145/3580305.3599783 | B20: ACM | C20: BOSS: A Bilateral Occupational-Suitability-Aware Recommender System for Online Recruitment | D20: With the rapid development of online recruitment platforms, a variety of emerging recommendation services have been witnessed for benefiting both job seekers and recruiters. While many researchers have studied the problem of reciprocal recommendation in two- sided markets (e.g., marriage market and real estate market), there is still a lack of in-depth understanding of the bilateral occupational preferences of different participants in the online recruitment market. To this end, in this paper, we propose a Bilateral Occupational-Suitability-aware recommender System (BOSS) for online recruitment, in consideration of the reciprocal, bilateral, and sequential properties of realistic recruitment scenarios simultaneously. To be specific, in BOSS, we first propose a multi-group-based mixture-of-experts (MoE) module to independently learn the preference representations of job seekers and recruiters. Then, with a specially-designed multi-task learning module, BOSS can progressively model the action sequence of recruitment process through a bilateral probabilistic manner. As a result, the reciprocal recommendations can be efficiently implemented by leveraging the product of different action probabilities of job seekers and recruiters. Finally, we have conducted extensive experiments on 5 real-world large-scale datasets as well as the online environment. Both online A/B test and offline experimental results clearly validate that our recommender system BOSS can outperform other state-of-the-art baselines with a significant margin. | E20: multi-task learning, online recruitment, reciprocal recommender systems | F20: 900 - No match | G20: 900 - No match | H20: [] | I20: [] | J20: =+LEN(H20) -> 2 | K20: =+LEN(I20) -> 2
A21: /doi/10.1145/2466627.2466649 | B21: ACM | C21: Unwrapping virtual space through the myth of total cinema | D21: Visionary promises of a 3D virtual future are unfulfilled. Online 3D platforms such as VRML, Second Life, and Open Sim sought a 3D web of worlds and delivered, at best, mixed results. To understand the broad creative and cognitive challenges that drive the design of 3D virtual spaces, a cross-disciplinary design review of early cinema, a technical precursor, is needed. 150 years ago, a simulation oriented "Myth of a Total Cinema" guided and limited the development of the earliest films (Bazin 1958, Manovich 2001). Cinema was first seen as a realistic mirror world made of captured images. It would take decades for film makers to discover how to leave the myth and create montage, literally breaking a simulated reality apart in service to narrative. This text retraces the creative process of discovery, the tension between montage and the myth of total cinema, and then proposes a virtual design foundation stemming from an overlooked aspect of videogame theory. | E21: cinema, film, interactivity, narrative, simulation, total cinema, videogame, virtual world | F21: 3 - Modified acrs | G21: 900 - No match | H21: ['VRML'] | I21: [] | J21: =+LEN(H21) -> 8 | K21: =+LEN(I21) -> 2
A22: /doi/10.1145/2990299.2990311 | B22: ACM | C22: Design of an expandable real-time simulation (eRTS) platform for multi-level rapid prototyping | D22: A real-time simulation (RTS) platform is a critical design and verification for rapidly designing and testing electrical and computing hardware as well as embedded software employed in real-time embedded applications, including an autonomous electric vehicle (AEV). We have developed a wirelessly expandable real-time simulation (eRTS) platform for mixed-level rapid prototyping of an AEV system. The eRTS platform consisting of a microkernel-based multi-core RTS and multiple monolithic-kernel console units is interoperable to FPGA-based virtual prototypes and further expandable to the real prototype via wireless (IEEE 802.15.4). The multi-core RTS and multi-console units are interfaced with high-speed wire/wireless (IEEE 802.3u/802.11g) for both software-/hardware-in-the-loops (SIL/HIL) simulations. In particular, the eRTS provides a mixed-level of intuitively expandable HIL simulations with software models and virtual/real prototypes. The proposed eRTS platform swiftly handles different scale and complexity of AEV testing at various development stages while satisfying real-time constraints (i.e., 7 Î¼s resolutions and 0.3% HIL simulation error) of the AEV software models and virtual/real prototypes. | E22: autonomous electric vehicle, hardware-in-the-loop simulation, rapid prototyping, real-time simulator | F22: 900 - No match | G22: 900 - No match | H22: [] | I22: [] | J22: =+LEN(H22) -> 2 | K22: =+LEN(I22) -> 2
A23: /doi/10.1145/3678591 | B23: ACM | C23: HabitSense: A Privacy-Aware, AI-Enhanced Multimodal Wearable Platform for mHealth Applications | D23: Wearable cameras provide an objective method to visually confirm and automate the detection of health-risk behaviors such as smoking and overeating, which is critical for developing and testing adaptive treatment interventions. Despite the potential of wearable camera systems, adoption is hindered by inadequate clinician input in the design, user privacy concerns, and user burden. To address these barriers, we introduced HabitSense, an open-source1, multi-modal neck-worn platform developed with input from focus groups with clinicians (N=36) and user feedback from in-wild studies involving 105 participants over 35 days. Optimized for monitoring health-risk behaviors, the platform utilizes RGB, thermal, and inertial measurement unit sensors to detect eating and smoking events in real time. In a 7-day study involving 15 participants, HabitSense recorded 768 hours of footage, capturing 420.91 minutes of hand-to-mouth gestures associated with eating and smoking data crucial for training machine learning models, achieving a 92% F1-score in gesture recognition. To address privacy concerns, the platform records only during likely health-risk behavior events using SECURE, a smart activation algorithm. Additionally, HabitSense employs on-device obfuscation algorithms that selectively obfuscate the background during recording, maintaining individual privacy while leaving gestures related to health-risk behaviors unobfuscated. Our implementation of SECURE has resulted in a 48% reduction in storage needs and a 30% increase in battery life. This paper highlights the critical roles of clinician feedback, extensive field testing, and privacy-enhancing algorithms in developing an unobtrusive, lightweight, and reproducible wearable system that is both feasible and acceptable for monitoring health-risk behaviors in real-world settings. | E23: camera, eating, machine learning, multimodal, privacy, smoking, thermal, vision transformers, wearable | F23: 900 - No match | G23: 900 - No match | H23: [] | I23: [] | J23: =+LEN(H23) -> 2 | K23: =+LEN(I23) -> 2
A24: /doi/10.1145/3581783.3612568 | B24: ACM | C24: Modal-aware Bias Constrained Contrastive Learning for Multimodal Recommendation | D24: Multimodal recommendation system has been widely used in short video platform, e-commerce platform and news media. Multimodal data contains information such as product image and product text, which is often used as auxiliary signal to improve the effect of recommendation system significantly. In order to alleviate the problems of data sparsity and noise, some researchers construct data augmentation to use self-supervised learning to help model training. These methods have achieved certain results. However, most of the work is based on data augmentation in random ways, such as random masking and random perturbation. This random method is likely to lose important information and introduce new noise, resulting in biased augmentation data. Therefore, we propose a Modal-aware Bias Constrained Contrastive Learning method (BCCL) to solve the above problems. Specifically, BCCL introduces a bias-constrained data augmentation method to ensure the quality of augmentation samples. Then the multi-modal semantic information is modeled by the designed modal awareness module. Furthermore, we propose a information alignment module to improve the sparse modal feature learning of the model. We conducted a comprehensive experiment on three real-world data sets, and the experimental results showed that the proposed BCCL outperformed all the state-of-art methods. In-depth experiments have verified the effectiveness of our proposed modules. | E24: bias constraint, contrastive learning, multimodal recommendation | F24: 900 - No match | G24: 900 - No match | H24: [] | I24: [] | J24: =+LEN(H24) -> 2 | K24: =+LEN(I24) -> 2
A25: /doi/10.1145/3614419.3644022 | B25: ACM | C25: Exploring Local Music's Place in Global Streaming | D25: Music is intertwined with geography as part of the cultural fabric that transforms a physical space into what we consider a â€œplace." But in an increasingly online world, where musicâ€™s distribution has shifted massively towards digital streaming on global platforms, what role does geography now play in shaping peoplesâ€™ music consumption? Here, we employ a multi-part, mixed-methods study of â€œlocal" music, exploring its current definition as well as exploring its potential role in online music recommender systems. We present, first, findings from a qualitative study designed to identify themes in how listeners and artists defined local music across three international locations. Second, we present results of a quantitative analysis that operationalizes this definition and investigates the impact of surfacing local context in a real-world recommendation setting, conducted in one location. Together, our results illustrate that â€œlocal" continues to play a crucial role in shaping musicâ€™s enjoyment and represents an important mechanism for facilitating the discovery of lesser-known artists in online algorithmic recommendations. | E25: Computational Social Science, Globalization, Music, Recommender Systems | F25: 900 - No match | G25: 900 - No match | H25: [] | I25: [] | J25: =+LEN(H25) -> 2 | K25: =+LEN(I25) -> 2
A26: /doi/10.1145/2731186.2731188 | B26: ACM | C26: HSPT: Practical Implementation and Efficient Management of Embedded Shadow Page Tables for Cross-ISA System Virtual Machines | D26: Cross-ISA (Instruction Set Architecture) system-level virtual machine has a significant research and practical value. For example, several recently announced virtual smart phones for iOS which run smart phone applications on x86 based PCs are deployed on cross-ISA system level virtual machines. Also, for mobile device application development, by emulating the Android/ARM environment on the more powerful x86-64 platform, application development and debugging become more convenient and productive. However, the virtualization layer often incurs high performance overhead. The key overhead comes from memory virtualization where a guest virtual address (GVA) must go through multi-level address translation to become a host physical address (HPA). The Embedded Shadow Page Table (ESPT) approach has been proposed to effectively decrease this address translation cost. ESPT directly maps GVA to HPA, thus avoid the lengthy guest virtual to guest physical, guest physical to host virtual, and host virtual to host physical address translation. However, the original ESPT work has a few drawbacks. For example, its implementation relies on a loadable kernel module (LKM) to manage the shadow page table. Using LKMs is less desirable for system virtual machines due to portability, security and maintainability concerns. Our work proposes a different, yet more practical, implementation to address the shortcomings. Instead of relying on using LKMs, our approach adopts a shared memory mapping scheme to maintain the shadow page table (SPT) using only ''mmap'' system call. Furthermore, this work studies the support of SPT for multi-processing in greater details. It devices three different SPT organizations and evaluates their strength and weakness with standard and real Android applications on the system virtual machine which emulates the Android/ARM platform on x86-64 systems. | E26: cross-isa virtualization, embedded shadow page table, hosted shadow page table, hspt, loadable kernel module, memory virtualization, portability, practical implementation, security | F26: 3 - Modified acrs | G26: 900 - No match | H26: ['ARM'] | I26: [] | J26: =+LEN(H26) -> 7 | K26: =+LEN(I26) -> 2
A27: /doi/10.1145/3488560.3498527 | B27: ACM | C27: Contrastive Meta Learning with Behavior Multiplicity for Recommendation | D27: A well-informed recommendation framework could not only help users identify their interested items, but also benefit the revenue of various online platforms (e.g., e-commerce, social media). Traditional recommendation models usually assume that only a single type of interaction exists between user and item, and fail to model the multiplex user-item relationships from multi-typed user behavior data, such as page view, add-to-favourite and purchase. While some recent studies propose to capture the dependencies across different types of behaviors, two important challenges have been less explored: i) Dealing with the sparse supervision signal under target behaviors (e.g., purchase). ii) Capturing the personalized multi-behavior patterns with customized dependency modeling. To tackle the above challenges, we devise a new model CML, Contrastive Meta Learning (CML), to maintain dedicated cross-type behavior dependency for different users. In particular, we propose a multi-behavior contrastive learning framework to distill transferable knowledge across different types of behaviors via the constructed contrastive loss. In addition, to capture the diverse multi-behavior patterns, we design a contrastive meta network to encode the customized behavior heterogeneity for different users. Extensive experiments on three real-world datasets indicate that our method consistently outperforms various state-of-the-art recommendation methods. Our empirical studies further suggest that the contrastive meta learning paradigm offers great potential for capturing the behavior multiplicity in recommendation. We release our model implementation at: https://github.com/weiwei1206/CML.git. | E27: collaborative filtering, graph neural network, meta learning, multi-behavior recommendation, self-supervised learning | F27: 900 - No match | G27: 2 - Complete terms | H27: [] | I27: ['collaborative'] | J27: =+LEN(H27) -> 2 | K27: =+LEN(I27) -> 17
A28: /doi/10.1145/3678717.3691312 | B28: ACM | C28: Regional Features Conditioned Diffusion Models for 5G Network Traffic Generation | D28: The fifth-generation (5G) mobile network has significantly enhanced people's lives with faster internet speed and more reliable connections. However, there is still insufficient coverage of 5G networks worldwide, requiring telecom operators to deploy more base stations to meet the increasing demand for 5G's further commercialization. In this regard, a major challenge is understanding user network behaviors and traffic demands in target areas where 5G has not yet been deployed, which is crucial for developing a more efficient base station deployment strategy. Mobile traffic generation is a potential approach that enables operators to preemptively estimate user network demands in target areas, thereby specifying corresponding deployment strategies to enhance network performance. However, existing methods have limitations in capturing spatio-temporal features of 5G mobile traffic, particularly in areas with insufficient 5G coverage and limited historical 5G traffic data. To fill this gap, we introduce a regional feature conditioned diffusion framework for 5G network traffic generation. Our models explore the relationship between 5G traffic and existing 4G traffic, utilizing a customized cross attention mechanism and graph convolutional networks (GCN) to capture the correlation between network traffic and regional features. Based on this relationship, the framework can characterize mobile network traffic demands, thereby achieving high-fidelity 5G traffic generation in target regions with insufficient 5G coverage. Extensive experiments on real-world datasets have shown that the proposed scheme outperforms state-of-the-art baselines by more than 10%, demonstrating its high-fidelity generation capability, controllability, and generalizability. Moreover, we have deployed our scheme on China Mobile's Jiutian Platform as a network traffic simulator to improve 5G base station deployment strategies. | E28: 5G network traffic generation, Cross attention, Diffusion models, GCN | F28: 900 - No match | G28: 900 - No match | H28: [] | I28: [] | J28: =+LEN(H28) -> 2 | K28: =+LEN(I28) -> 2
... A30: /doi/10.1145/3659154.3659192 | B30: ACM | C30: An MEC-based Platform for IoT Applications | D30: The key technologies for the future development of mobile communications are: Provide end-to-end ultra-low latency, reliability and availability; Provide different network slices according to different business needs; Provide edge computing power; Smart network manage. Ultra-low latency and reliability and the ability to handle large-scale Internet of Things (IoT) connections are two important requirements. However, this cannot be achieved by simply improving the performance of wireless transmission (e.g. the radio access network). It is also necessary to improve the core network and creates edge computing platforms to achieve this goal. To address this issue, this article develops and deploys a mobile edge computing platform, also known as a multi-access edge computing (MEC) platform, to meet the requirements of ultra-low latency, high reliability, and massive connections. This article takes a smart pig farm as an example to demonstrate the design and deployment of an MEC applications. Specifically, this article develops an IoT system for the pig farm on the MEC platform and creates a virtualized MEC application to provide real-time packet processing and image recognition for the pig farm monitoring. In addition, this paper analyzes the performance of this MEC App, including the recognition accuracy and the latency in error recovery of the MEC App. | E30: Artificial Intelligence, CCS CONCEPTS:Wireless Networks, Networks | F30: 900 - No match | G30: 900 - No match | H30: [] | I30: [] | J30: =+LEN(H30) -> 2 | K30: =+LEN(I30) -> 2
A31: /doi/10.14778/3611540.3611617 | B31: ACM | C31: FS-Real: A Real-World Cross-Device Federated Learning Platform | D31: Federated learning (FL) is a general distributed machine learning paradigm that provides solutions for tasks where data cannot be shared directly. Due to the difficulties in communication management and heterogeneity of distributed data and devices, initiating and using an FL algorithm for real-world cross-device scenarios requires significant repetitive effort but may not be transferable to similar projects. To reduce the effort required for developing and deploying FL algorithms, we present FS-Real, an open-source FL platform designed to address the need of a general and efficient infrastructure for real-world cross-device FL. In this paper, we introduce the key components of FS-Real and demonstrate that FS-Real has the following capabilities: 1) reducing the programming burden of FL algorithm development with plug-and-play and adaptable runtimes on Android and other Internet of Things (IoT) devices; 2) handling a large number of heterogeneous devices efficiently and robustly with our communication management components; 3) supporting a wide range of advanced FL algorithms with flexible configuration and extension; 4) alleviating the costs and efforts for deployment, evaluation, simulation, and performance optimization of FL algorithms with automatized tool kits. | F31: 900 - No match | G31: 900 - No match | H31: [] | I31: [] | J31: =+LEN(H31) -> 2 | K31: =+LEN(I31) -> 2
A32: /doi/10.1145/3637528.3671528 | B32: ACM | C32: Know in AdVance: Linear-Complexity Forecasting of Ad Campaign Performance with Evolving User Interest | D32: Real-time Bidding (RTB) advertisers wish to | E32: campaign performance forecasting, real-time bidding, sequence modeling, user interest modeling | F32: 900 - No match | G32: 900 - No match | H32: [] | I32: [] | J32: =+LEN(H32) -> 2 | K32: =+LEN(I32) -> 2
A33: /doi/10.1145/3711912 | B33: ACM | C33: Unsupervised Framing Analysis for Social Media Discourse in Polarizing Events | D33: This study investigates the concept of | E33: Framing Analysis, Polarization, Social Network Analysis | F33: 900 - No match | G33: 900 - No match | H33: [] | I33: [] | J33: =+LEN(H33) -> 2 | K33: =+LEN(I33) -> 2
A34: /doi/10.1145/3637528.3671509 | B34: ACM | C34: FusionSF: Fuse Heterogeneous Modalities in a Vector Quantized Framework for Robust Solar Power Forecasting | D34: Accurate solar power forecasting is crucial to integrate photovoltaic plants into the electric grid, schedule and secure the power grid safety. This problem becomes more demanding for those newly installed solar plants which lack sufficient operational data. Current research predominantly relies on historical solar power data or numerical weather prediction in a single-modality format, ignoring the complementary information provided in different modalities. In this paper, we propose a multi-modality fusion framework to integrate historical power data, numerical weather prediction, and satellite images, significantly improving forecast performance. We introduce a vector quantized framework that aligns modalities with varying information densities, striking a balance between integrating sufficient information and averting model overfitting. Our framework demonstrates strong zero-shot forecasting capability, which is especially useful for those newly installed plants. Moreover, we collect and release a multi-modal solar power (MMSP) dataset from real-world plants to further promote the research of multi-modal solar forecasting algorithms. Our extensive experiments show that our model not only operates with robustness but also boosts accuracy in both zero-shot forecasting and scenarios rich with training data, surpassing leading models. We have incorporated it into our eForecaster platform and deployed it for more than 300 solar plants with a total capacity of over 15GW. Our code and dataset are accessible at https://github.com/DAMO-DI-ML/FusionSF.git. | E34: modality fusion, solar power forecasting, vector quantization, zero-shot learning | F34: 900 - No match | G34: 900 - No match | H34: [] | I34: [] | J34: =+LEN(H34) -> 2 | K34: =+LEN(I34) -> 2
A35: /doi/10.5555/3581644.3581711 | B35: ACM | C35: Performability Assessment of Containerized Multi-Tenant IMS through Multidimensional UGF | D35: We advance a performability assessment of a multi-tenant containerized IP Multimedia Subsystem (cIMS), i.e.: one and the same infrastructure is shared among different providers (or tenants). Specifically, we: | E35: IP multimedia subsystem, performability, redundancy optimization, universal generating function | F35: 900 - No match | G35: 900 - No match | H35: [] | I35: [] | J35: =+LEN(H35) -> 2 | K35: =+LEN(I35) -> 2
A36: /doi/10.1145/3555041.3589672 | B36: ACM | C36: Growing and Serving Large Open-domain Knowledge Graphs | D36: Applications of large open-domain knowledge graphs (KGs) to real-world problems pose many unique challenges. In this paper, we present extensions to Saga our platform for continuous construction and serving of knowledge at scale. In particular, we describe a pipeline for training knowledge graph embeddings that powers key capabilities such as fact ranking, fact verification, a related entities service, and support for entity linking. We then describe how our platform, including graph embeddings, can be leveraged to create a Semantic Annotation service that links unstructured Web documents to entities in our KG. Semantic annotation of the Web effectively expands our knowledge graph with edges to open-domain Web content which can be used in various search and ranking problems. Finally, we leverage annotated Web documents to drive Open-domain Knowledge Extraction. This targeted extraction framework identifies important coverage issues in the KG, then finds relevant data sources for target entities on the Web and extracts missing information to enrich the KG. Finally, we describe adaptations to our knowledge platform needed to construct and serve private personal knowledge on-device. This includes private incremental KG construction, cross- device knowledge sync, and global knowledge enrichment. | E36: information extraction, knowledge graphs, semantic annotation | F36: 900 - No match | G36: 900 - No match | H36: [] | I36: [] | J36: =+LEN(H36) -> 2 | K36: =+LEN(I36) -> 2
A37: /doi/10.1145/3589334.3645468 | B37: ACM | C37: MSynFD: Multi-hop Syntax Aware Fake News Detection | D37: The proliferation of social media platforms has fueled the rapid dissemination of fake news, posing threats to our real-life society. Existing methods use multimodal data or contextual information to enhance the detection of fake news by analyzing news content and/or its social context. However, these methods often overlook essential textual news content (articles) and heavily rely on sequential modeling and global attention to extract semantic information. These existing methods fail to handle the complex, subtle twists | E37: debiasing, fake news detection, graph neural network | F37: 900 - No match | G37: 900 - No match | H37: [] | I37: [] | J37: =+LEN(H37) -> 2 | K37: =+LEN(I37) -> 2
A38: /doi/10.1145/3495243.3560522 | B38: ACM | C38: A-mash: providing single-app illusion for multi-app use through user-centric UI mashup | D38: Mobile apps offer a variety of features that greatly enhance user experience. However, users still often find it difficult to use mobile apps in the way they want. For example, it is not easy to use multiple apps simultaneously on a small screen of a smartphone. In this paper, we present A-Mash, a mobile platform that aims to simplify the way of interacting with multiple apps concurrently to the level of using a single app only. A key feature of A-Mash is that users can | E38: mobile platform, multi app execution, multi-app single-screen, multi-tasking, user interface mashup | F38: 900 - No match | G38: 900 - No match | H38: [] | I38: [] | J38: =+LEN(H38) -> 2 | K38: =+LEN(I38) -> 2
A39: /doi/10.1145/3423459.3430760 | B39: ACM | C39: COVID-19 Joint Pandemic Modeling and Analysis Platform | D39: The non-pharmaceutical intervention to reduce the impact and spread of COVID-19 requires the development of policies and guidance through a collaborative effort among government, academia, medicine, and citizens. To operationalize this effort, we have developed an all-encompassing situational awareness platform that can process multi-modal and multi-source data allowing informed decision making. Besides, showing the current spread of infection, the platform also captures the impact of human dynamics on the infection spread, location, and availability of critical infrastructure, prediction, and high-performance computing driven simulation. The platform is extensible, allowing third-party integration and services to consume the curated data and analytics in near real-time. We believe the platform will augment critical decision making for reducing the impact and spread of the pandemic. | E39: distributed systems, real-time architectures, visualization | F39: 900 - No match | G39: 2 - Complete terms | H39: [] | I39: ['collaborative'] | J39: =+LEN(H39) -> 2 | K39: =+LEN(I39) -> 17
A40: /doi/10.1145/3510427.3510432 | B40: ACM | C40: Simulations of MRI Guided and Powered Ferric Applicators for Tetherless Delivery of Therapeutic Interventions | D40: Magnetic Resonance Imaging (MRI) is a well-established modality for pre-operative planning and is also explored for intra-operative guidance of procedures such as intravascular interventions. Among the experimental robot-assisted technologies, the magnetic field gradients of the MRI scanner are used to power and maneuver ferromagnetic applicators for accessing sites in the patientâ€™s body via the vascular network. In this work, we propose a computational platform for preoperative planning and modeling of MRI-powered applicators inside blood vessels. This platform was implemented as a two-way data and command pipeline that links the MRI scanner, the computational core, and the operator. The platform first processes multi-slice MR data to extract the vascular bed and then fits a virtual corridor inside the vessel. This corridor serves as a virtual fixture (VF), a forbidden region for the applicators to avoid vessel perforation or collision. The geometric features of the vessel centerline, the VF, and MRI safety compliance (dB/dt, max available gradient) are then used to generate magnetic field gradient waveforms. Different blood flow profiles can be user-selected, and those parameters are used for modeling the applicatorâ€™s maneuvering. The modeling module further generates cues about whether the selected vascular path can be safely maneuvered. Given future experimental studies that require a real-time operation, the platform was implemented on the Qt framework (C/C++) with software modules performing specific tasks running on dedicated threads: PID controller, generation of VF, generation of MR gradient waveforms. | E40: MRI, PID, VF, blood flow, blood vessels | F40: 2 - Complete acrs | G40: 900 - No match | H40: ['virtual environment', 'MRI', 'MR'] | I40: [] | J40: =+LEN(H40) -> 36 | K40: =+LEN(I40) -> 2
A41: /doi/10.1145/3626772.3657786 | B41: ACM | C41: DeCoCDR: Deployable Cloud-Device Collaboration for Cross-Domain Recommendation | D41: Cross-domain recommendation (CDR) is a widely used methodology in recommender systems to combat data sparsity. It leverages user data across different domains or platforms for providing personalized recommendations. Traditional CDR assumes user preferences and behavior data can be shared freely among cloud and users, which is now impractical due to strict restrictions of data privacy. In this paper, we propose a Deployment-friendly Cloud-Device Collaboration framework for Cross-Domain Recommendation (DeCoCDR). It splits CDR into a two-stage recommendation model through cloud-device collaborations, i.e., item-recall on cloud and item re-ranking on device. This design enables effective CDR while preserving data privacy for both the cloud and the device. Extensive offline and online experiments are conducted to validate the effectiveness of DeCoCDR. In offline experiments, DeCoCDR outperformed the state-of-the-arts in three large datasets. While in real-world deployment, DeCoCDR improved the conversion rate by 45.3% compared with the baseline. | E41: cloud-device collaboration, cross-domain recommendation, on-device inference, privacy presevation | F41: 900 - No match | G41: 2 - Complete terms | H41: [] | I41: ['collaboration'] | J41: =+LEN(H41) -> 2 | K41: =+LEN(I41) -> 17
...

Sheet Sheet1
A1: Category technology | B1: Subcategory of interest | C1: Marked as included
A2: 1 - Complete terms | B2: 1 - Complete terms cross | C2: x | D2: =+COUNTIFS(output_file_it3!$F$2:$F$17170,A2,output_file_it3!$G$2:$G$17170,B2) -> 165 | E2: =+D2/$D$18 -> 0.065947242
A3: 1 - Complete terms | B3: 2 - Complete terms | D3: =+COUNTIFS(output_file_it3!$F$2:$F$17170,A3,output_file_it3!$G$2:$G$17170,B3) -> 123 | E3: =+D3/$D$18 -> 0.049160671
A4: 1 - Complete terms | B4: 3 - Regex terms | D4: =+COUNTIFS(output_file_it3!$F$2:$F$17170,A4,output_file_it3!$G$2:$G$17170,B4) -> 11 | E4: =+D4/$D$18 -> 0.0043964828 | H4: Papers of iterest | I4: =+SUMIFS($D$2:$D$17,$C$2:$C$17,"x") -> 220
A5: 1 - Complete terms | B5: 900 - No match | D5: =+COUNTIFS(output_file_it3!$F$2:$F$17170,A5,output_file_it3!$G$2:$G$17170,B5) -> 470 | E5: =+D5/$D$18 -> 0.18784972 | I5: =+I4/D18 -> 0.087929656
A6: 2 - Complete acrs | B6: 1 - Complete terms cross | C6: x | D6: =+COUNTIFS(output_file_it3!$F$2:$F$17170,A6,output_file_it3!$G$2:$G$17170,B6) -> 6 | E6: =+D6/$D$18 -> 0.0023980815
